<?xml version='1.0'?>
<sdf version='1.4'>
    <model name="robot">
        <static>false</static>
        <link name="chassis">
            <pose>0 0 0.04 0 0 0</pose>
            <collision name="collision>">
                <geometry>
                    <cylinder>
                        <radius>0.1</radius>
                        <length>0.04</length>
                    </cylinder>
                </geometry>
            </collision>
            <visual name="visual">
                <geometry>
                    <cylinder>
                        <radius>0.1</radius>
                        <length>0.04</length>
                    </cylinder>
                </geometry>
            </visual>
            <collision name='caster_front_collision'>
                <pose>0.07 0 -0.02 0 0 0</pose>
                    <geometry>
                        <sphere>
                            <radius>.02</radius>
                        </sphere>
                    </geometry>
                <surface>
                    <friction>
                        <ode>
                            <mu>0</mu>
                            <mu2>0</mu2>
                            <slip1>1.0</slip1>
                            <slip2>1.0</slip2>
                        </ode>
                    </friction>
                </surface>
            </collision>
            <visual name='caster_front_visual'>
                <pose>0.07 0 -0.02 0 0 0</pose>
                <geometry>
                    <sphere>
                        <radius>.02</radius>
                    </sphere>
                </geometry>
            </visual>
            <collision name='caster_back_collision'>
                <pose>-0.07 0 -0.02 0 0 0</pose>
                    <geometry>
                        <sphere>
                            <radius>.02</radius>
                        </sphere>
                    </geometry>
                <surface>
                    <friction>
                        <ode>
                            <mu>0</mu>
                            <mu2>0</mu2>
                            <slip1>1.0</slip1>
                            <slip2>1.0</slip2>
                        </ode>
                    </friction>
                </surface>
            </collision>
            <visual name='caster_back_visual'>
                <pose>-0.07 0 -0.02 0 0 0</pose>
                <geometry>
                    <sphere>
                        <radius>.02</radius>
                    </sphere>
                </geometry>
            </visual>
        </link>
        <link name="left_wheel">
            <pose>0 0.11 0.04 0 1.5707 1.5707</pose>
            <collision name="collision">
                <geometry>
                    <cylinder>
                        <radius>.04</radius>
                        <length>.02</length>
                    </cylinder>
                </geometry>
            </collision>
            <visual name="visual">
                <geometry>
                    <cylinder>
                        <radius>.04</radius>
                        <length>.02</length>
                    </cylinder>
                </geometry>
            </visual>
        </link>
        <link name="right_wheel">
            <pose>0 -0.11 0.04 0 1.5707 1.5707</pose>
            <collision name="collision">
                <geometry>
                    <cylinder>
                        <radius>.04</radius>
                        <length>.02</length>
                    </cylinder>
                </geometry>
            </collision>
            <visual name="visual">
                <geometry>
                    <cylinder>
                        <radius>.04</radius>
                        <length>.02</length>
                    </cylinder>
                </geometry>
            </visual>
        </link>
        <joint type="revolute" name="left_wheel_hinge">
            <pose>0 0 0 0 0 0</pose>
            <child>left_wheel</child>
            <parent>chassis</parent>
            <axis>
                <xyz>0 1 0</xyz>
            </axis>
        </joint>

        <joint type="revolute" name="right_wheel_hinge">
            <pose>0 0 0 0 0 0</pose>
            <child>right_wheel</child>
            <parent>chassis</parent>
            <axis>
                <xyz>0 1 0</xyz>
            </axis>
        </joint>
        <include>
            <uri>model://hokuyo</uri>
            <pose>0.07 0 0.09 0 0 0</pose>
        </include>
        <joint name="hokuyo_joint" type="fixed">
            <child>hokuyo::link</child>
            <parent>chassis</parent>
        </joint>
    </model>
</sdf>